Workbook

Sheet 00 · LÉEME
A1: ETC 88 · PRESUPUESTO MAESTRO — TABLERO
A2: Retiro 4–6 sep 2026 · Casa La Ceiba del Salado, Higüey · 100 pers. base (50 part. + 50 equipo cubierto; 53 equipo total con 3 asesores externos) · Co-Dir. Juan Manuel
A4: INDICADORES CLAVE (vivos)
A5: COSTO TOTAL (LADO A) | C5: COSTO POR PERSONA | E5: DÍAS AL RETIRO
A6: ='01 · LADO A Costos'!O14 | C6: ='01 · LADO A Costos'!O14/100 | E6: =DATE(2026,9,4)-TODAY()
A8: CUOTAS FIRMES | C8: COBERTURA (cuotas/total) | E8: BRECHA TRAS CUOTAS
A9: ='02 · LADO B Recaudación'!D8 | C9: ='02 · LADO B Recaudación'!D8/'01 · LADO A Costos'!O14 | E9: ='02 · LADO B Recaudación'!D20
A11: PALANCAS ESTIMADAS | C11: VALOR DONABLE (especie) | E11: % CASA SOBRE EL TOTAL
A12: ='02 · LADO B Recaudación'!D15 | C12: ='02 · LADO B Recaudación'!D34 | E12: ='01 · LADO A Costos'!O5/'01 · LADO A Costos'!O14
A14: NAVEGACIÓN
A15: ▶ 01 · LADO A Costos | B15: Costos detallados, ordenables por precio/volumen/categoría
A16: ▶ 02 · LADO B Recaudación | B16: Cuotas firmes, palancas, ecuación de brecha, escenarios
A17: ▶ 03 · Calendario | B17: Cronograma Jun–Ago + flujo de caja proyectado
A18: ▶ 04 · Caja | B18: Movimientos reales de tesorería (saldo vivo)
A19: ▶ 05 · Benchmarks | B19: Lecciones de ETC 78/79/83/85/86
A20: ▶ 06 · Cuotas | B20: Qué cubre cada cuota (participante vs equipo) y cobertura real
A22: DESGLOSE POR RUBRO (vivo)
A23: Rubro | B23: Subtotal | C23: % del total
A24: 1 · Casa | B24: ='01 · LADO A Costos'!O5 | C24: ='01 · LADO A Costos'!O5/'01 · LADO A Costos'!O14
A25: 2 · Cocina | B25: ='01 · LADO A Costos'!O6 | C25: ='01 · LADO A Costos'!O6/'01 · LADO A Costos'!O14
A26: 3 · Transporte | B26: ='01 · LADO A Costos'!O7 | C26: ='01 · LADO A Costos'!O7/'01 · LADO A Costos'!O14
A27: 4 · Biblias y peces | B27: ='01 · LADO A Costos'!O8 | C27: ='01 · LADO A Costos'!O8/'01 · LADO A Costos'!O14
A28: 5 · Guías/Eventos/Música/Camisetas | B28: ='01 · LADO A Costos'!O9 | C28: ='01 · LADO A Costos'!O9/'01 · LADO A Costos'!O14
A29: 6 · Litúrgico | B29: ='01 · LADO A Costos'!O10 | C29: ='01 · LADO A Costos'!O10/'01 · LADO A Costos'!O14
A30: 7 · Avanzada | B30: ='01 · LADO A Costos'!O11 | C30: ='01 · LADO A Costos'!O11/'01 · LADO A Costos'!O14
A31: TOTAL LADO A | B31: ='01 · LADO A Costos'!O14 | C31: 1
A33: DECISIONES PENDIENTES (resolver con el equipo)
A34: Tema | B34: Situación / opciones | F34: Estado
A35: Exención casa | B35: 2,000/pers (con exención) vs 2,300 (sin). Gestionar con parroquia. Vale 30,000. | F35: Por confirmar
A36: Tamaño equipo | B36: RESUELTO (Carpeta): 53 titulares · 48 operativos en el retiro. Casa usa 48 equipo; camisetas 53. | F36: Resuelto
A37: Nº de participantes | B37: Casa asume 50 part. (estimado). Confirmar lista real de participantes. | F37: Por confirmar
A38: Cuotas | B38: Vigente 3,000/2,000 vs histórico 2,500/1,500. | F38: Vigente
A39: Transporte | B39: 3 buses POR COTIZAR (15,000 + 34,000 + 28,500 estimados). | F39: Cotizar
A40: Avanzada | B40: Sin estimado (0). Definir hospedaje+comida 15–20 pers jue/vie. | F40: Falta dato
A41: Movimiento salón | B41: Aporte/pago 10,000 a Franklin Pozo: ¿entrada o salida? | F41: Por confirmar
A42: Responsable Tesorería | B42: No nombrado (lección ETC 85). Bloquea operar el modelo. | F42: Nombrar
A43: Ítems cocina no verificados | B43: Té frío, sazón, orégano, puerro, bizcocho, salsa roja kg. | F43: Verificar
A44: Donaciones en especie | B44: Hasta 114,701 potencial; confirmar biblias/peces/café/arroz. | F44: Gestionar
A46: CÓMO USAR
A47: 1. Edita SOLO celdas amarillas (cantidades, precios, cuotas, entradas/salidas). El resto son fórmulas.
...

Sheet 01 · LADO A Costos
A1: ETC 88 · LADO A — COSTOS (tabla ordenable: filtra/ordena por precio, volumen o categoría)
A2: 4–6 sep 2026 · Casa La Ceiba del Salado, Higüey · 100 pers. base (50 part. + 50 equipo cubierto; 53 equipo total con 3 asesores externos) · precios cocina jun-2026
N3: RESUMEN LADO A
A4: Rubro | B4: Categoría | C4: Ítem | D4: Cant. | E4: Unidad | F4: P. Unit | G4: Subtotal | H4: % costo | I4: Proveedor / Fuente | J4: Estado | K4: Donable | L4: Nota | N4: Rubro | O4: Subtotal
A5: 1 · Casa | B5: Hospedaje | C5: Hospedaje 100 pers. (3 días) | D5: 100 | E5: Persona | F5: 2000 | G5: =D5*F5 | H5: =G5/SUM($G$5:$G$74) | I5: Casa La Ceiba del Salado, Higüey | J5: Estimado | K5: N | L5: 50 part. + 50 equipo cubierto (3 asesores externos auto-cubren su estadía). Con exención 2,000; sin exención 2,300 (+30,000). CONFIRMAR tarifa 2026. | N5: 1 · Casa | O5: =SUMIF($A$5:$A$74,N5,$G$5:$G$74)
A6: 2 · Cocina | B6: Vegetal/Fruta | C6: Plátano verde | D6: 180 | E6: Unidad | F6: 24 | G6: =D6*F6 | H6: =G6/SUM($G$5:$G$74) | I6: S.Nacional | J6: Estimado | K6: N | L6: Nacional 24 (Jumbo 21) | N6: 2 · Cocina | O6: =SUMIF($A$5:$A$74,N6,$G$5:$G$74)
A7: 2 · Cocina | B7: Proteína | C7: Pechuga de pollo (con hueso) | D7: 50 | E7: Libra | F7: 135 | G7: =D7*F7 | H7: =G7/SUM($G$5:$G$74) | I7: Jumbo/Nacional | J7: Estimado | K7: N | L7: 134.95/lb. ↓ vs 160 | N7: 3 · Transporte | O7: =SUMIF($A$5:$A$74,N7,$G$5:$G$74)
A8: 2 · Cocina | B8: Proteína | C8: Carne de res para guisar | D8: 45 | E8: Libra | F8: 265 | G8: =D8*F8 | H8: =G8/SUM($G$5:$G$74) | I8: Jumbo | J8: Estimado | K8: N | L8: ⚠️ 264.95/lb (subió vs 170). Revisar corte | N8: 4 · Biblias y peces | O8: =SUMIF($A$5:$A$74,N8,$G$5:$G$74)
A9: 2 · Cocina | B9: Vegetal/Fruta | C9: Papa | D9: 64 | E9: Libra | F9: 45 | G9: =D9*F9 | H9: =G9/SUM($G$5:$G$74) | I9: S.Nacional | J9: Estimado | K9: N | L9: Malla 5lb ~45/lb | N9: 5 · Guías/Eventos/Música/Camisetas | O9: =SUMIF($A$5:$A$74,N9,$G$5:$G$74)
A10: 2 · Cocina | B10: Vegetal/Fruta | C10: Cebolla roja | D10: 8 | E10: Libra | F10: 49 | G10: =D10*F10 | H10: =G10/SUM($G$5:$G$74) | I10: Sirena | J10: Estimado | K10: N | L10: Criolla 49/lb | N10: 6 · Litúrgico | O10: =SUMIF($A$5:$A$74,N10,$G$5:$G$74)
A11: 2 · Cocina | B11: Vegetal/Fruta | C11: Ají morrón | D11: 7 | E11: Libra | F11: 83 | G11: =D11*F11 | H11: =G11/SUM($G$5:$G$74) | I11: S.Nacional | J11: Estimado | K11: N | L11: Rojo 83/lb | N11: 7 · Avanzada | O11: =SUMIF($A$5:$A$74,N11,$G$5:$G$74)
A12: 2 · Cocina | B12: Vegetal/Fruta | C12: Tomate barceló | D12: 10 | E12: Libra | F12: 42 | G12: =D12*F12 | H12: =G12/SUM($G$5:$G$74) | I12: Garrido | J12: Estimado | K12: N | L12: Bugalú/Barceló 42/lb | N12: Subtotal operativo | O12: =SUM($G$5:$G$74)
A13: 2 · Cocina | B13: Proteína | C13: Chuleta ahumada | D13: 6 | E13: Libra | F13: 129 | G13: =D13*F13 | H13: =G13/SUM($G$5:$G$74) | I13: S.Nacional | J13: Estimado | K13: N | L13: Cerdo 129/lb | N13: Imprevistos / contingencia (10%) | O13: =ROUND(0.10*O12,0)
A14: 2 · Cocina | B14: Proteína | C14: Salami (barra Induveca 2.25lb) | D14: 3 | E14: Barra | F14: 430 | G14: =D14*F14 | H14: =G14/SUM($G$5:$G$74) | I14: Nacional/Plaza Lama | J14: Estimado | K14: N | L14: 2.25lb ~430; grande 3.5lb 479-514 | N14: TOTAL LADO A | O14: =O12+O13
A15: 2 · Cocina | B15: Lácteo/Huevo | C15: Huevos | D15: 6 | E15: Cartón 30 | F15: 215 | G15: =D15*F15 | H15: =G15/SUM($G$5:$G$74) | I15: S.Nacional | J15: Estimado | K15: N | L15: Líder 214.95. ↓ vs 250
A16: 2 · Cocina | B16: Proteína | C16: Jamón cocido rebanado | D16: 6 | E16: Libra | F16: 155 | G16: =D16*F16 | H16: =G16/SUM($G$5:$G$74) | I16: S.Nacional | J16: Estimado | K16: N | L16: El Pozo 154.95 reg (oferta 129.95) | N16: MENÚ por categoría (cocina)
A17: 2 · Cocina | B17: Lácteo/Huevo | C17: Queso amarillo/cheddar rebanado | D17: 5 | E17: Libra | F17: 345 | G17: =D17*F17 | H17: =G17/SUM($G$5:$G$74) | I17: Jumbo/Nacional | J17: Estimado | K17: N | L17: ⚠️ ~345/lb (subió vs 260) | N17: Categoría | O17: Subtotal
A18: 2 · Cocina | B18: Víveres/Grano | C18: Pasta espagueti | D18: 15 | E18: Paq 400g | F18: 42 | G18: =D18*F18 | H18: =G18/SUM($G$5:$G$74) | I18: Nacional/Jumbo | J18: Estimado | K18: N | L18: Milano 400g 41.95 | N18: Proteína | O18: =SUMIFS($G$5:$G$74,$A$5:$A$74,"2 · Cocina",$B$5:$B$74,N18)
A19: 2 · Cocina | B19: Víveres/Grano | C19: Espirales pasta | D19: 8 | E19: Paq 400g | F19: 42 | G19: =D19*F19 | H19: =G19/SUM($G$5:$G$74) | I19: Nacional/Jumbo | J19: Estimado | K19: N | L19: Milano coditos 41.95 | N19: Lácteo/Huevo | O19: =SUMIFS($G$5:$G$74,$A$5:$A$74,"2 · Cocina",$B$5:$B$74,N19)
A20: 2 · Cocina | B20: Lácteo/Huevo | C20: Leche entera | D20: 5 | E20: Caja 12L | F20: 912 | G20: =D20*F20 | H20: =G20/SUM($G$5:$G$74) | I20: PriceSmart/Jumbo | J20: Estimado | K20: N | L20: Listamilk Rica ~76/L → ~912 (ESTIMADO) | N20: Víveres/Grano | O20: =SUMIFS($G$5:$G$74,$A$5:$A$74,"2 · Cocina",$B$5:$B$74,N20)
A21: 2 · Cocina | B21: Lácteo/Huevo | C21: Leche evaporada | D21: 15 | E21: Lata 315g | F21: 67 | G21: =D21*F21 | H21: =G21/SUM($G$5:$G$74) | I21: Jumbo/Nacional | J21: Estimado | K21: N | L21: Carnation 66.95 | N21: Vegetal/Fruta | O21: =SUMIFS($G$5:$G$74,$A$5:$A$74,"2 · Cocina",$B$5:$B$74,N21)
A22: 2 · Cocina | B22: Bebida/Café | C22: Café Santo Domingo 1lb | D22: 8 | E22: Paq 1lb | F22: 419 | G22: =D22*F22 | H22: =G22/SUM($G$5:$G$74) | I22: Jumbo | J22: Estimado | K22: S | L22: 418.95 (oferta 399). ⚠️ buscar donación | N22: Aceite/Grasa | O22: =SUMIFS($G$5:$G$74,$A$5:$A$74,"2 · Cocina",$B$5:$B$74,N22)
A23: 2 · Cocina | B23: Víveres/Grano | C23: Azúcar crema | D23: 4 | E23: Paq 5lb | F23: 157 | G23: =D23*F23 | H23: =G23/SUM($G$5:$G$74) | I23: Jumbo/Nacional | J23: Estimado | K23: N | L23: Líder 157 / Nacional 150. ↓ vs 170 | N23: Condimento | O23: =SUMIFS($G$5:$G$74,$A$5:$A$74,"2 · Cocina",$B$5:$B$74,N23)
A24: 2 · Cocina | B24: Litúrgico | C24: Vino la Fuerza (litúrgico) | D24: 2 | E24: Galón | F24: 525 | G24: =D24*F24 | H24: =G24/SUM($G$5:$G$74) | I24: Nacional/BebidasRD | J24: Estimado | K24: S | L24: 1gl ~525-550; ½gl 399; 70cl 235. Donable parroquia | N24: Bebida/Café | O24: =SUMIFS($G$5:$G$74,$A$5:$A$74,"2 · Cocina",$B$5:$B$74,N24)
A25: 2 · Cocina | B25: Aceite/Grasa | C25: Mayonesa Baldom | D25: 2 | E25: Galón | F25: 795 | G25: =D25*F25 | H25: =G25/SUM($G$5:$G$74) | I25: S.Nacional | J25: Estimado | K25: N | L25: ⚠️ 794.95 (subió fuerte vs 550) | N25: Pan/Snack/Dulce | O25: =SUMIFS($G$5:$G$74,$A$5:$A$74,"2 · Cocina",$B$5:$B$74,N25)
A26: 2 · Cocina | B26: Aceite/Grasa | C26: Aceite de freír | D26: 1 | E26: Galón 128oz | F26: 634 | G26: =D26*F26 | H26: =G26/SUM($G$5:$G$74) | I26: Jumbo/Nacional | J26: Estimado | K26: S | L26: Crisol 128oz 634 | N26: Litúrgico | O26: =SUMIFS($G$5:$G$74,$A$5:$A$74,"2 · Cocina",$B$5:$B$74,N26)
A27: 2 · Cocina | B27: Lácteo/Huevo | C27: Crema de leche | D27: 5 | E27: Lata 300g | F27: 150 | G27: =D27*F27 | H27: =G27/SUM($G$5:$G$74) | I27: S.Nacional | J27: Estimado | K27: N | L27: Nestlé 300g 149.95. ↓ vs 300 | N27: Limpieza | O27: =SUMIFS($G$5:$G$74,$A$5:$A$74,"2 · Cocina",$B$5:$B$74,N27)
A28: 2 · Cocina | B28: Víveres/Grano | C28: Harina de trigo | D28: 20 | E28: Libra | F28: 42 | G28: =D28*F28 | H28: =G28/SUM($G$5:$G$74) | I28: S.Nacional | J28: Estimado | K28: N | L28: Blanquita 2lb 83.95 → ~42/lb | N28: Desechable | O28: =SUMIFS($G$5:$G$74,$A$5:$A$74,"2 · Cocina",$B$5:$B$74,N28)
A29: 2 · Cocina | B29: Pan/Snack/Dulce | C29: Galletas Guarina Salada | D29: 15 | E29: Paq 12 | F29: 59 | G29: =D29*F29 | H29: =G29/SUM($G$5:$G$74) | I29: S.Nacional | J29: Estimado | K29: N | L29: Saladitas 58.95 | N29: Enlatado | O29: =SUMIFS($G$5:$G$74,$A$5:$A$74,"2 · Cocina",$B$5:$B$74,N29)
A30: 2 · Cocina | B30: Pan/Snack/Dulce | C30: Galletas Guarina Dulce | D30: 15 | E30: Paq 12 | F30: 81 | G30: =D30*F30 | H30: =G30/SUM($G$5:$G$74) | I30: Casa Surtidora | J30: Estimado | K30: N | L30: Guarina Leche 12u 80.95. ↓ vs 115
A31: 2 · Cocina | B31: Bebida/Café | C31: Refrescos doble litro | D31: 14 | E31: Unidad 2L | F31: 92 | G31: =D31*F31 | H31: =G31/SUM($G$5:$G$74) | I31: Nacional/Jumbo | J31: Estimado | K31: N | L31: Coca-Cola 2L 91.95
A32: 2 · Cocina | B32: Pan/Snack/Dulce | C32: Chocolate molido | D32: 6 | E32: Pote 200g | F32: 109 | G32: =D32*F32 | H32: =G32/SUM($G$5:$G$74) | I32: S.Nacional | J32: Estimado | K32: N | L32: Embajador molido 108.95. ↓ vs 175
A33: 2 · Cocina | B33: Bebida/Café | C33: Té frío (sobres) | D33: 4 | E33: Caja | F33: 470 | G33: =D33*F33 | H33: =G33/SUM($G$5:$G$74) | I33: — | J33: Estimado | K33: N | L33: NO encontrado en cadenas; mantiene ref. VERIFICAR
A34: 2 · Cocina | B34: Pan/Snack/Dulce | C34: Pan baguette | D34: 40 | E34: Unidad | F34: 50 | G34: =D34*F34 | H34: =G34/SUM($G$5:$G$74) | I34: La Panera | J34: Estimado | K34: N | L34: Sobao La Panera 10u=60 (~6/u) alt.
A35: 2 · Cocina | B35: Pan/Snack/Dulce | C35: Pan rebanado grande | D35: 4 | E35: Funda | F35: 215 | G35: =D35*F35 | H35: =G35/SUM($G$5:$G$74) | I35: S.Nacional | J35: Estimado | K35: N | L35: Lumijor/molde 214.95-274.95. ↑ vs 120
A36: 2 · Cocina | B36: Limpieza | C36: Papel de baño | D36: 2 | E36: Fardo 24 | F36: 360 | G36: =D36*F36 | H36: =G36/SUM($G$5:$G$74) | I36: S.Nacional | J36: Estimado | K36: N | L36: Líder 24u 359.95 (oferta 304.95). ↓ vs 475
A37: 2 · Cocina | B37: Limpieza | C37: Mistolín | D37: 2 | E37: Galón | F37: 335 | G37: =D37*F37 | H37: =G37/SUM($G$5:$G$74) | I37: S.Nacional | J37: Estimado | K37: N | L37: Mistolín 1gl 334.95
A38: 2 · Cocina | B38: Limpieza | C38: Cloro | D38: 2 | E38: Galón | F38: 135 | G38: =D38*F38 | H38: =G38/SUM($G$5:$G$74) | I38: Plaza Lama/Jumbo | J38: Estimado | K38: N | L38: Líder/Macier 1gl ~129-140
A39: 2 · Cocina | B39: Limpieza | C39: Escoba | D39: 3 | E39: Unidad | F39: 170 | G39: =D39*F39 | H39: =G39/SUM($G$5:$G$74) | I39: S.Nacional | J39: Estimado | K39: S | L39: Escoba Líder ~170; pedir prestada
A40: 2 · Cocina | B40: Limpieza | C40: Suape | D40: 3 | E40: Unidad | F40: 220 | G40: =D40*F40 | H40: =G40/SUM($G$5:$G$74) | I40: S.Nacional | J40: Estimado | K40: S | L40: Suaper Líder ~220; pedir prestada
...

Sheet 02 · LADO B Recaudación
A1: ETC 88 · LADO B — RECAUDACIÓN Y BRECHA
A2: Solo las CUOTAS son ingreso firme. Meta: cubrir el LADO A (break-even). Celdas amarillas = editables.
A4: 1 · INGRESOS FIRMES — CUOTAS
A5: Fuente | B5: Personas | C5: Cuota (RD$) | D5: Ingreso | E5: Estado | F5: Nota
A6: Cuota participantes | B6: 50 | C6: 3000 | D6: =B6*C6 | E6: Firme | F6: 1er + 2do pago (50 estimado)
A7: Cuota equipo | B7: 53 | C7: 2000 | D7: =B7*C7 | E7: Firme | F7: 53 titulares (Carpeta)
A8: Subtotal cuotas (FIRME) | D8: =SUM(D6:D7)
A9: 2 · PALANCAS DE RECAUDACIÓN (estimadas — no firmes)
A10: Fuente | B10: Parámetro | C10: Parámetro | D10: Meta (RD$) | E10: Prob. | F10: Nota
A11: Rifa / Profondo #1 | B11: 600 | C11: 200 | D11: =B11*C11-30000 | E11: Media | F11: 600 boletos × 200 − premio 30,000 (neto en cronograma Ago)
A12: Venta de garaje | D12: 60000 | E12: Media | F12: Donación de artículos para vender
A13: Venta de comida (2-3 eventos) | D13: 25000 | E13: Media | F13: Sancochos / chercas (2 eventos × 12,500)
A14: Donaciones en efectivo | D14: 40000 | E14: Media | F14: Parroquia, padrinos, diáspora
A15: Subtotal palancas (estimado) | D15: =SUM(D11:D14)
A17: 3 · ECUACIÓN DE COBERTURA (brecha vinculada en vivo al LADO A)
A18: TOTAL LADO A (costo del retiro) | D18: ='01 · LADO A Costos'!O14
A19: (−) Cuotas firmes | D19: =-D8
A20: =BRECHA tras cuotas | D20: ='01 · LADO A Costos'!O14-D8
A21: (−) Palancas de caja (estimadas) | D21: =-D15
A22: (−) Donaciones en especie (reducen el costo) | D22: =-SUMIF('01 · LADO A Costos'!K5:K74,"S",'01 · LADO A Costos'!G5:G74)
A23: =SUPERÁVIT / (DÉFICIT) proyectado [+ sobra / − falta] | D23: =D8+D15+SUMIF('01 · LADO A Costos'!K5:K74,"S",'01 · LADO A Costos'!G5:G74)-'01 · LADO A Costos'!O14
A25: 4 · ESCENARIOS DE CUOTA (impacto en la brecha)
A26: Escenario | B26: Cuota part. | C26: Cuota equipo | D26: Ingreso cuotas | E26: Brecha tras cuotas | F26: Nota
A27: A · Actual (recomendado) | B27: 3000 | C27: 2000 | D27: =50*B27+53*C27 | E27: ='01 · LADO A Costos'!O14-D27 | F27: 50 part. + 50 equipo
A28: B · Sube participante | B28: 3500 | C28: 2000 | D28: =50*B28+53*C28 | E28: ='01 · LADO A Costos'!O14-D28 | F28: +500 part.
A29: C · Baja equipo | B29: 3000 | C29: 1500 | D29: =50*B29+53*C29 | E29: ='01 · LADO A Costos'!O14-D29 | F29: −500 equipo
A30: D · Ambas suben | B30: 3500 | C30: 2500 | D30: =50*B30+53*C30 | E30: ='01 · LADO A Costos'!O14-D30 | F30: colchón mayor
A32: 5 · DONACIONES EN ESPECIE (potencial — bajan la brecha peso a peso)
A33: Ítems marcados 'Donable = S' en el LADO A. Si se consiguen donados (biblias, peces, café, arroz, habichuelas, aceite, camisetas, etc.), su valor sale del costo y reduce la brecha directamente.
A34: Valor donable potencial (LADO A) | D34: =SUMIF('01 · LADO A Costos'!K5:K74,"S",'01 · LADO A Costos'!G5:G74)

Sheet 03 · Calendario
A1: ETC 88 · CALENDARIO Y FLUJO DE CAJA (Jun–Sep 2026)
A2: Ventana de recaudación Jun–Ago; ejecución de pagos en Sep. Celdas amarillas = editables. Especie no entra como caja (reduce costo).
A4: A · CRONOGRAMA DE RECAUDACIÓN (Plan A — meta de caja 471,000)
A5: Mes | B5: Hito / Actividad | C5: Fuente | D5: Meta RD$ | E5: Responsable | F5: Estado
A6: Jun | B6: 1er pago de cuotas (50 part. + 53 equipo) | C6: Cuotas | D6: 128000 | E6: Tesorería | F6: En curso
A7: Jun | B7: Lanzar rifa / profondo (600 boletos) | C7: Rifa | D7: — | E7: Comisión rifa | F7: En curso
A8: Jun | B8: Gestionar donaciones en especie | C8: Especie | D8: (114,701) | E8: Todo el equipo | F8: En curso
A9: Jul | B9: 2do pago de cuotas | C9: Cuotas | D9: 128000 | E9: Tesorería | F9: Pendiente
A10: Jul | B10: Venta de garaje (artículos donados) | C10: Garaje | D10: 60000 | E10: Comisión eventos | F10: Pendiente
A11: Jul | B11: Venta de comida #1 (sancocho/cherca) | C11: Comida | D11: 12500 | E11: Comisión cocina | F11: Pendiente
A12: Ago | B12: Sorteo de la rifa | C12: Rifa | D12: 90000 | E12: Comisión rifa | F12: Pendiente
A13: Ago | B13: Venta de comida #2 | C13: Comida | D13: 12500 | E13: Comisión cocina | F13: Pendiente
A14: Ago | B14: Cierre de donaciones en efectivo | C14: Efectivo | D14: 40000 | E14: Tesorería | F14: Pendiente
B15: Total caja recaudable (Plan A) | D15: =SUMIF(C6:C14,"<>Especie",D6:D14)
A17: B · FLUJO DE CAJA PROYECTADO (saldo acumulado = saldo viva)
A18: Mes | B18: Entradas RD$ | C18: Salidas RD$ | D18: Saldo del mes | E18: Saldo acumulado
A19: Jun | B19: 128000 | C19: 60000 | D19: =B19-C19 | E19: =D19 | F19: Salón pagado + anticipo casa
A20: Jul | B20: 200500 | C20: 81000 | D20: =B20-C20 | E20: =E19+D20 | F20: Biblias, peces, materiales guías
A21: Ago | B21: 142500 | C21: 88750 | D21: =B21-C21 | E21: =E20+D21 | F21: Anticipo transporte, camisetas, no perecederos
A22: Sep | B22: 0 | C22: 209171 | D22: =B22-C22 | E22: =E21+D22 | F22: ⚠️ MES PICO: casa, perecederos, transporte, ofrendas, imprevistos 10%
A23: TOTAL | B23: =SUM(B19:B22) | C23: =SUM(C19:C22) | D23: =B23-C23 | E23: =E22
A25: Saldo acumulado final = margen sobre el LADO A (caja). Salidas excluyen especie donada (~114,701). El mes pico es septiembre: asegurar liquidez ANTES del retiro.

Sheet 04 · Caja
A1: ETC 88 · CAJA — MOVIMIENTOS REALES (Tesorería)
A2: Registro de dinero efectivamente movido. Saldo = fórmula viva. Confirmar dirección/medio de cada movimiento con Tesorería.
A4: Fecha | B4: Concepto | C4: Tipo | D4: Entrada RD$ | E4: Salida RD$ | F4: Medio | G4: Referencia / Responsable | H4: Saldo
A5: 2026-06-07 | B5: Reserva de la casa (depósito) | C5: Salida | D5: 0 | E5: 23600 | F5: Transferencia | G5: Casa La Ceiba del Salado | H5: =D5-E5
A6: 2026-06-07 | B6: Reserva devuelta | C6: Entrada | D6: 23600 | E6: 0 | F6: Transferencia | G6: Casa La Ceiba del Salado | H6: =H5+D6-E6
A7: 2026-06-07 | B7: Aporte personal J.M. (cubre salón) | C7: Entrada | D7: 10000 | E7: 0 | F7: Aporte personal | G7: Juan Manuel (Co-Dir.) | H7: =H6+D7-E7
A8: 2026-06-07 | B8: Pago de salón | C8: Salida | D8: 0 | E8: 10000 | F8: Efectivo | G8: Franklin Pozo | H8: =H7+D8-E8
B9: SALDO EN CAJA | D9: =SUM(D5:D8) | E9: =SUM(E5:E8) | H9: =H8
A11: DEUDAS POR REEMBOLSAR (aportes personales — el grupo debe devolverlos)
A12: Acreedor | B12: Concepto | D12: Monto RD$ | F12: Fecha | G12: Estado | H12: Saldo
A13: Juan Manuel (Co-Dir.) | B13: Salón pagado de su dinero personal | D13: 10000 | F13: 2026-06-07 | G13: Pendiente
A14: TOTAL ADEUDADO | D14: =SUM(D13:D13)

Sheet 05 · Benchmarks
A1: ETC 88 · BENCHMARKS Y LECCIONES (ETC 78 / 83 / 85 / 86)
A2: Referencia histórica real (ETC 83 cocina y concierto; Carpeta ETC 88). No recalcula el modelo; orienta decisiones.
A4: A · CONSOLIDADO MULTI-EDICIÓN (78·79·83·85·86 → 88) — cantidades, rubros y alcances
A5: Métrica | B5: Histórico (78·79·83·85·86) | C5: ETC 88 (2026) | D5: Lectura
A6: Participantes | B6: 36–47 | C6: 50 | D6: El MÁS grande del histórico reciente
A7: Equipo total | B7: 36–48 | C7: 53 / 50 cubierto | D7: En el techo; cerrar nº temprano (lección 85)
A8: Asesores externos | B8: 4 (86) | C8: 3 | D8: Misma estructura; pagan su cuota
A9: Cuota participante | B9: 2,000–4,800 | C9: 3,000 | D9: Media-baja; SD(86) cobró 4,800
A10: Cuota equipo | B10: 300–2,000 | C10: 2,000 | D10: =SD(86) 2,000 y los asesores la pagan ✅
A11: Casa | B11: 50,000 fijo (78/79) · 4,000/pers (86) | C11: 2,000/pers = 200,000 | D11: Modelo POR PERSONA validado; tu tarifa es la mitad de SD
A12: Buses | B12: 1–2 | C12: 3 | D12: Verificar si 2 cubren
A13: Cocina / mercado | B13: 82,738 (83) | C13: 72,778 | D13: Optimizado, ítems comparables
A14: Imprevistos | B14: 10% (83), fijo (86) | C14: 10% | D14: Alineado
A15: Palanca recaudación #1 | B15: Concierto 447K (86) o venta garaje (78/79) | C15: Profondo: rifa+garaje+comida | D15: ETC 88 SIN estructura de concierto → vía profondo
A17: B · COSTOS REALES ETC 83 — COCINA (gold standard de precios)
A18: Partida | B18: Monto RD$ | D18: Comentario
A19: Lista del Mercado | B19: 82,738 | D19: 57+ ítems con precio unitario (2024)
A20: Lista Correcaminos (frutas/pan/gas) | B20: 8,370 | D20: Aparte del mercado
A21: Materiales/detalles (subtotal) | B21: 11,520 | D21: +10% imprevistos = 12,672
A22: Estado de cuentas cocina | B22: -1,653 | D22: Gastó 15,253 vs aportes 13,600 → DÉFICIT
A24: C · BENCHMARK DE RECAUDACIÓN — Concierto «Teofanía de Amor» (2017)
A25: Concepto | B25: Monto RD$ | D25: Detalle
A26: Venta de taquillas | B26: 149,500 | D26: ~600 taquillas — la fuente #1
A27: Venta de artículos (camisetas, etc.) | B27: 56,450 | D27: Antes/durante/después
A28: Venta de comida | B28: 17,440 | D28: En el evento
A29: Patrocinio | B29: 23,300 | D29: Empresas/padrinos
A30: Donaciones + especie | B30: 14,600 | D30: Efectivo + hielo/agua/sillas
A31: TOTAL INGRESOS | B31: 274,045 | D31: —
A32: (−) Gastos del evento | B32: 127,692 | D32: Artistas, lugar, audiovisual, promo
A33: =UTILIDAD NETA | B33: 146,353 | D33: Un evento cubrió >½ de una brecha tipo ETC 88
A34: ℹ️ Referencia, NO plan para ETC 88: el concierto es la palanca de quien tiene la estructura para montarlo (SD/86 neteó 447K; Teofanía 146K). DECISIÓN ETC 88: recaudar vía actividades pro-fondo (rifa + venta de garaje + venta de comida), no un concierto.
A36: D · LECCIONES DE GOBERNANZA (ETC 85 + estado de cuentas ETC 83)
A37: • Nombrar un responsable único de Tesorería/Finanzas ANTES de recaudar.
A38: • Doble firma para egresos sobre 5,000; cuenta separada del retiro.
A39: • Fondo de reserva (~2.5% del total) para imprevistos de último momento.
A40: • Límites de gasto por área (cocina, guías, música) acordados al inicio.
A41: • Comparar planificado vs. real cada semana; conservar todos los recibos.
A42: • La casa suele ser el mayor riesgo (38–40%); asegurar tarifa y exención temprano.
A43: • ETC 83 cocina cerró en DÉFICIT (-1,653): los aportes del área no alcanzaron — fijar meta de aportes por área.
A45: E · ETC 86 (SANTO DOMINGO) — PRESUPUESTO EJECUTADO REAL (gold standard de granularidad)
...

Sheet 06 · Cuotas
A1: ETC 88 · QUÉ CUBRE CADA CUOTA (participante vs equipo)
A2: Mapeo cuota → costo: qué financia cada cuota, qué se completa con palancas/especie y qué partidas son flotantes (van a Guías o Cocina, no a una cuota).
A4: A · MAPEO CUOTA → COSTO
A5: Cuota | B5: Monto | C5: Qué cubre directamente | D5: Se completa con
A6: Participante | B6: 3000 | C6: Transporte al retiro · comida del retiro · casa (hospedaje) · pez · biblia | D6: Palancas + especie cubren el resto de su costo real (~5,536/pers), que la cuota no alcanza
A7: Equipo | B7: 2000 | C7: Ensayo general (solo equipo; el participante no va) · prorrateo del alquiler del salón · transporte al retiro · comida del ensayo general · camiseta del equipo | D7: 3 asesores externos pagan su cuota pero auto-cubren su estadía y no llevan camiseta
A9: B · ANÁLISIS DE COBERTURA (cuota vs costo real) — vínculos vivos
A10: Concepto | B10: Valor | D10: Nota
A11: Costo por persona (LADO A / 100) | B11: ='01 · LADO A Costos'!O14/100 | D11: Promedio sobre 100 cubiertos
A12: Cuota participante | B12: 3000 | D12: Confirmada
A13: =Déficit por participante | B13: =3000-'01 · LADO A Costos'!O14/100 | D13: Lo que NO cubre su cuota (lo tapan palancas/especie)
A14: Cuota equipo | B14: 2000 | D14: Confirmada (incl. 3 asesores externos)
A15: =Déficit por equipo cubierto (aprox.) | B15: =2000-'01 · LADO A Costos'!O14/100 | D15: Aprox.: equipo no lleva biblia/pez pero suma ensayo+salón+camiseta
A16: Cuotas firmes totales | B16: ='02 · LADO B Recaudación'!D8 | D16: 50×3,000 + 53×2,000
A17: Cobertura cuotas / LADO A | B17: ='02 · LADO B Recaudación'!D8/'01 · LADO A Costos'!O14 | D17: El resto exige recaudación
A19: C · PARTIDAS FLOTANTES (no las cubre una cuota; van a Guías o Cocina)
A20: • Banderín → presupuesto de Guías/Eventos.
A21: • Liturgia (formas, vino, ofrenda) → presupuesto de Guías/Litúrgico.
A22: • Detalles / regalos → Guías/Eventos.
A23: • Biblia y materiales del participante → bloque de Biblias/Materiales (no sale directo de su cuota).
A25: ⭐ Lectura: la cuota del participante (3,000) NO cubre su costo real (~5,536) — déficit estructural ~2,536/part. que palancas y especie compensan. Por eso ~54% del LADO A exige recaudación.
